Workbook

Sheet Nov2022
C1: =IFERROR(__xludf.DUMMYFUNCTION("SPARKLINE((SUM(B16:H16)+3*SUM(T15:U15) + SUM(K16:Q16) + SUM(B33:H33) + SUM(K33:Q33) + 3*SUM(T32:U32)+ 5*SUM(X19))/45,{""charttype"",""bar"";""max"",1;""min"",0;""color1"",IF((SUM(B16:H16)+3*SUM(T15:U15) + SUM(K16:Q16) + SUM(B33:H33) + SUM(K33:Q33) + 3*SUM"&"(T32:U32)+ 5*SUM(X19))/45>0.7,""green"",IF((SUM(B16:H16)+3*SUM(T15:U15) + SUM(K16:Q16) + SUM(B33:H33) + SUM(K33:Q33) + 3*SUM(T32:U32)+ 5*SUM(X19))/45>0.5,""yellow"",""red""))})"),"") | R1: =(SUM(B16:H16)+3*SUM(T15:U15) + SUM(K16:Q16) + SUM(B33:H33) + SUM(K33:Q33) + 3*SUM(T32:U32) + 5*SUM(X19))/45 -> 0.73050505 | S1: Points | T1: {=COUNTIF(B5:H15,TRUE)+COUNTIF(K5:Q15,TRUE)+COUNTIF(B22:H32,TRUE)+COUNTIF(K22:Q32,TRUE)+3*(COUNTIF(T5:U14,TRUE)+COUNTIF(T22:U31,TRUE))+5*(COUNTIF(X15:X18,TRUE))} -> 317
A2: 44866
A3: Week 1 | B3: =DATE(YEAR(A2),MONTH(A2),1)+MOD(9-WEEKDAY(DATE(YEAR(A2),MONTH(A2),1)),7) -> 44872 | C3: =B3+1 -> 44873 | D3: =C3+1 -> 44874 | E3: =D3+1 -> 44875 | F3: =E3+1 -> 44876 | G3: =F3+1 -> 44877 | H3: =G3+1 -> 44878 | J3: Week 2 | K3: =H3+1 -> 44879 | L3: =K3+1 -> 44880 | M3: =L3+1 -> 44881 | N3: =M3+1 -> 44882 | O3: =N3+1 -> 44883 | P3: =O3+1 -> 44884 | Q3: =P3+1 -> 44885
A4: Day | B4: =CHOOSE(WEEKDAY(B3,2),"Mon","Tue","Wed","Thu","Fri","Sat","Sun") -> Mon | C4: =CHOOSE(WEEKDAY(C3,2),"Mon","Tue","Wed","Thu","Fri","Sat","Sun") -> Tue | D4: =CHOOSE(WEEKDAY(D3,2),"Mon","Tue","Wed","Thu","Fri","Sat","Sun") -> Wed | E4: =CHOOSE(WEEKDAY(E3,2),"Mon","Tue","Wed","Thu","Fri","Sat","Sun") -> Thu | F4: =CHOOSE(WEEKDAY(F3,2),"Mon","Tue","Wed","Thu","Fri","Sat","Sun") -> Fri | G4: =CHOOSE(WEEKDAY(G3,2),"Mon","Tue","Wed","Thu","Fri","Sat","Sun") -> Sat | H4: =CHOOSE(WEEKDAY(H3,2),"Mon","Tue","Wed","Thu","Fri","Sat","Sun") -> Sun | J4: Day | K4: =CHOOSE(WEEKDAY(K3,2),"Mon","Tue","Wed","Thu","Fri","Sat","Sun") -> Mon | L4: =CHOOSE(WEEKDAY(L3,2),"Mon","Tue","Wed","Thu","Fri","Sat","Sun") -> Tue | M4: =CHOOSE(WEEKDAY(M3,2),"Mon","Tue","Wed","Thu","Fri","Sat","Sun") -> Wed | N4: =CHOOSE(WEEKDAY(N3,2),"Mon","Tue","Wed","Thu","Fri","Sat","Sun") -> Thu | O4: =CHOOSE(WEEKDAY(O3,2),"Mon","Tue","Wed","Thu","Fri","Sat","Sun") -> Fri | P4: =CHOOSE(WEEKDAY(P3,2),"Mon","Tue","Wed","Thu","Fri","Sat","Sun") -> Sat | Q4: =CHOOSE(WEEKDAY(Q3,2),"Mon","Tue","Wed","Thu","Fri","Sat","Sun") -> Sun | S4: Weekly Goals | T4: Week 1 | U4: Week 2
A5: Exercise | B5: FALSE | C5: FALSE | D5: FALSE | E5: FALSE | F5: FALSE | G5: FALSE | H5: FALSE | J5: Exercise | K5: FALSE | L5: FALSE | M5: TRUE | N5: TRUE | O5: TRUE | P5: TRUE | Q5: TRUE | S5: Laundry | T5: TRUE | U5: TRUE
A6: Stretch/Yoga (>20min) | B6: FALSE | C6: FALSE | D6: FALSE | E6: FALSE | F6: FALSE | G6: FALSE | H6: FALSE | J6: Stretch/Yoga (>20min) | K6: FALSE | L6: FALSE | M6: FALSE | N6: TRUE | O6: TRUE | P6: TRUE | Q6: TRUE | S6: Cleaning | T6: TRUE | U6: TRUE
A7: Social Media (<Limit) | B7: TRUE | C7: TRUE | D7: TRUE | E7: TRUE | F7: TRUE | G7: FALSE | H7: TRUE | J7: Social Media (<Limit) | K7: TRUE | L7: TRUE | M7: TRUE | N7: TRUE | O7: TRUE | P7: TRUE | Q7: TRUE | S7: Grocery Shop | T7: TRUE | U7: TRUE
A8: Eat in | B8: FALSE | C8: TRUE | D8: TRUE | E8: TRUE | F8: TRUE | G8: TRUE | H8: FALSE | J8: Eat in | K8: TRUE | L8: TRUE | M8: TRUE | N8: TRUE | O8: TRUE | P8: TRUE | Q8: TRUE | S8: Meal Prep | T8: TRUE | U8: TRUE
A9: Review Budget/Goals | B9: TRUE | C9: TRUE | D9: TRUE | E9: TRUE | F9: TRUE | G9: TRUE | H9: TRUE | J9: Review Budget/Goals | K9: TRUE | L9: TRUE | M9: TRUE | N9: TRUE | O9: TRUE | P9: TRUE | Q9: TRUE | S9: Website work (~2h) | T9: FALSE | U9: FALSE
A10: Brush Teeth (>=2) | B10: TRUE | C10: TRUE | D10: TRUE | E10: TRUE | F10: TRUE | G10: TRUE | H10: TRUE | J10: Brush Teeth (>=2) | K10: TRUE | L10: TRUE | M10: TRUE | N10: TRUE | O10: TRUE | P10: TRUE | Q10: TRUE | S10: Recycling | T10: TRUE | U10: TRUE
A11: Water (>2.25) | B11: FALSE | C11: FALSE | D11: FALSE | E11: FALSE | F11: FALSE | G11: FALSE | H11: FALSE | J11: Water (>2.25) | K11: FALSE | L11: FALSE | M11: TRUE | N11: TRUE | O11: TRUE | P11: TRUE | Q11: TRUE | S11: Trash | T11: TRUE | U11: TRUE
A12: 7 hours sleep | B12: TRUE | C12: FALSE | D12: TRUE | E12: TRUE | F12: TRUE | G12: TRUE | H12: FALSE | J12: 7 hours sleep | K12: TRUE | L12: FALSE | M12: TRUE | N12: TRUE | O12: FALSE | P12: TRUE | Q12: TRUE | S12: Shave/Trim | T12: FALSE | U12: TRUE
A13: Clean (~20 min) | B13: FALSE | C13: TRUE | D13: FALSE | E13: TRUE | F13: FALSE | G13: FALSE | H13: TRUE | J13: Clean (~20 min) | K13: TRUE | L13: TRUE | M13: FALSE | N13: TRUE | O13: TRUE | P13: TRUE | Q13: TRUE | S13: Water Plants | T13: TRUE | U13: FALSE
A14: Read (~20 min) | B14: FALSE | C14: FALSE | D14: FALSE | E14: FALSE | F14: FALSE | G14: FALSE | H14: FALSE | J14: Read (~20 min) | K14: FALSE | L14: FALSE | M14: FALSE | N14: FALSE | O14: TRUE | P14: TRUE | Q14: FALSE | S14: Weekend Exercise | T14: FALSE | U14: TRUE | W14: Monthly Goals
A15: Vitamins | B15: TRUE | C15: TRUE | D15: TRUE | E15: TRUE | F15: TRUE | G15: TRUE | H15: TRUE | J15: Vitamins | K15: TRUE | L15: TRUE | M15: TRUE | N15: TRUE | O15: TRUE | P15: TRUE | Q15: TRUE | S15: Total | T15: =COUNTIF(T5:T14,True)/COUNTA(T5:T14) -> 0.7 | U15: =COUNTIF(U5:U14,True)/COUNTA(U5:U14) -> 0.8 | W15: Wash Sheets | X15: TRUE
A16: Total | B16: =COUNTIF(B5:B15,True)/COUNTA(B5:B15) -> 0.45454545 | C16: =COUNTIF(C5:C15,True)/COUNTA(C5:C15) -> 0.54545455 | D16: =COUNTIF(D5:D15,True)/COUNTA(D5:D15) -> 0.54545455 | E16: =COUNTIF(E5:E15,True)/COUNTA(E5:E15) -> 0.63636364 | F16: =COUNTIF(F5:F15,True)/COUNTA(F5:F15) -> 0.54545455 | G16: =COUNTIF(G5:G15,True)/COUNTA(G5:G15) -> 0.45454545 | H16: =COUNTIF(H5:H15,True)/COUNTA(H5:H15) -> 0.45454545 | J16: Total | K16: =COUNTIF(K5:K15,True)/COUNTA(K5:K15) -> 0.63636364 | L16: =COUNTIF(L5:L15,True)/COUNTA(L5:L15) -> 0.54545455 | M16: =COUNTIF(M5:M15,True)/COUNTA(M5:M15) -> 0.72727273 | N16: =COUNTIF(N5:N15,True)/COUNTA(N5:N15) -> 0.90909091 | O16: =COUNTIF(O5:O15,True)/COUNTA(O5:O15) -> 0.90909091 | P16: =COUNTIF(P5:P15,True)/COUNTA(P5:P15) -> 1 | Q16: =COUNTIF(Q5:Q15,True)/COUNTA(Q5:Q15) -> 0.90909091 | S16: Progress bar | T16: =IFERROR(__xludf.DUMMYFUNCTION("SPARKLINE(T15,{""charttype"",""bar"";""max"",1;""min"",0;""color1"",IF(T15>0.7,""green"",IF(T15>0.5,""yellow"",""red""))})"),"") | U16: =IFERROR(__xludf.DUMMYFUNCTION("SPARKLINE(U15,{""charttype"",""bar"";""max"",1;""min"",0;""color1"",IF(U15>0.7,""green"",IF(U15>0.5,""yellow"",""red""))})"),"") | W16: Savings Deposit | X16: TRUE
A17: Daily Progress | B17: =IFERROR(__xludf.DUMMYFUNCTION("SPARKLINE(B16,{""charttype"",""bar"";""max"",1;""min"",0;""color1"",IF(B16>0.7,""green"",IF(B16>0.5,""yellow"",""red""))})"),"") | C17: =IFERROR(__xludf.DUMMYFUNCTION("SPARKLINE(C16,{""charttype"",""bar"";""max"",1;""min"",0;""color1"",IF(C16>0.7,""green"",IF(C16>0.5,""yellow"",""red""))})"),"") | D17: =IFERROR(__xludf.DUMMYFUNCTION("SPARKLINE(D16,{""charttype"",""bar"";""max"",1;""min"",0;""color1"",IF(D16>0.7,""green"",IF(D16>0.5,""yellow"",""red""))})"),"") | E17: =IFERROR(__xludf.DUMMYFUNCTION("SPARKLINE(E16,{""charttype"",""bar"";""max"",1;""min"",0;""color1"",IF(E16>0.7,""green"",IF(E16>0.5,""yellow"",""red""))})"),"") | F17: =IFERROR(__xludf.DUMMYFUNCTION("SPARKLINE(F16,{""charttype"",""bar"";""max"",1;""min"",0;""color1"",IF(F16>0.7,""green"",IF(F16>0.5,""yellow"",""red""))})"),"") | G17: =IFERROR(__xludf.DUMMYFUNCTION("SPARKLINE(G16,{""charttype"",""bar"";""max"",1;""min"",0;""color1"",IF(G16>0.7,""green"",IF(G16>0.5,""yellow"",""red""))})"),"") | H17: =IFERROR(__xludf.DUMMYFUNCTION("SPARKLINE(H16,{""charttype"",""bar"";""max"",1;""min"",0;""color1"",IF(H16>0.7,""green"",IF(H16>0.5,""yellow"",""red""))})"),"") | J17: Daily Progress | K17: =IFERROR(__xludf.DUMMYFUNCTION("SPARKLINE(K16,{""charttype"",""bar"";""max"",1;""min"",0;""color1"",IF(K16>0.7,""green"",IF(K16>0.5,""yellow"",""red""))})"),"") | L17: =IFERROR(__xludf.DUMMYFUNCTION("SPARKLINE(L16,{""charttype"",""bar"";""max"",1;""min"",0;""color1"",IF(L16>0.7,""green"",IF(L16>0.5,""yellow"",""red""))})"),"") | M17: =IFERROR(__xludf.DUMMYFUNCTION("SPARKLINE(M16,{""charttype"",""bar"";""max"",1;""min"",0;""color1"",IF(M16>0.7,""green"",IF(M16>0.5,""yellow"",""red""))})"),"") | N17: =IFERROR(__xludf.DUMMYFUNCTION("SPARKLINE(N16,{""charttype"",""bar"";""max"",1;""min"",0;""color1"",IF(N16>0.7,""green"",IF(N16>0.5,""yellow"",""red""))})"),"") | O17: =IFERROR(__xludf.DUMMYFUNCTION("SPARKLINE(O16,{""charttype"",""bar"";""max"",1;""min"",0;""color1"",IF(O16>0.7,""green"",IF(O16>0.5,""yellow"",""red""))})"),"") | P17: =IFERROR(__xludf.DUMMYFUNCTION("SPARKLINE(P16,{""charttype"",""bar"";""max"",1;""min"",0;""color1"",IF(P16>0.7,""green"",IF(P16>0.5,""yellow"",""red""))})"),"") | Q17: =IFERROR(__xludf.DUMMYFUNCTION("SPARKLINE(Q16,{""charttype"",""bar"";""max"",1;""min"",0;""color1"",IF(Q16>0.7,""green"",IF(Q16>0.5,""yellow"",""red""))})"),"") | W17: Loan Payment | X17: TRUE
A18: Weekly Progress | B18: =IFERROR(__xludf.DUMMYFUNCTION("SPARKLINE((SUM(B16:H16)+3*T15)/10,{""charttype"",""bar"";""max"",1;""min"",0;""color1"",IF((SUM(B16:H16)+3*T15)/10>0.7,""green"",IF((SUM(B16:H16)+3*T15)/10>0.5,""yellow"",""red""))})"),"") | J18: Weekly Progress | K18: =IFERROR(__xludf.DUMMYFUNCTION("SPARKLINE((SUM(K16:Q16)+3*U15)/10,{""charttype"",""bar"";""max"",1;""min"",0;""color1"",IF((SUM(K16:Q16)+3*U15)/10>0.7,""green"",IF((SUM(K16:Q16)+3*U15)/10>0.5,""yellow"",""red""))})"),"") | W18: Wash mats | X18: TRUE
W19: Total | X19: =COUNTIF(X15:X18,True)/COUNTA(X15:X18) -> 1
A20: Week 3 | B20: =Q3+1 -> 44886 | C20: =B20+1 -> 44887 | D20: =C20+1 -> 44888 | E20: =D20+1 -> 44889 | F20: =E20+1 -> 44890 | G20: =F20+1 -> 44891 | H20: =G20+1 -> 44892 | J20: Week 4 | K20: =H20+1 -> 44893 | L20: =K20+1 -> 44894 | M20: =L20+1 -> 44895 | N20: =M20+1 -> 44896 | O20: =N20+1 -> 44897 | P20: =O20+1 -> 44898 | Q20: =P20+1 -> 44899 | W20: Progress bar | X20: =IFERROR(__xludf.DUMMYFUNCTION("SPARKLINE(X19,{""charttype"",""bar"";""max"",1;""min"",0;""color1"",IF(X19>0.7,""green"",IF(X19>0.5,""yellow"",""red""))})"),"")
A21: Day | B21: =CHOOSE(WEEKDAY(B20,2),"Mon","Tue","Wed","Thu","Fri","Sat","Sun") -> Mon | C21: =CHOOSE(WEEKDAY(C20,2),"Mon","Tue","Wed","Thu","Fri","Sat","Sun") -> Tue | D21: =CHOOSE(WEEKDAY(D20,2),"Mon","Tue","Wed","Thu","Fri","Sat","Sun") -> Wed | E21: =CHOOSE(WEEKDAY(E20,2),"Mon","Tue","Wed","Thu","Fri","Sat","Sun") -> Thu | F21: =CHOOSE(WEEKDAY(F20,2),"Mon","Tue","Wed","Thu","Fri","Sat","Sun") -> Fri | G21: =CHOOSE(WEEKDAY(G20,2),"Mon","Tue","Wed","Thu","Fri","Sat","Sun") -> Sat | H21: =CHOOSE(WEEKDAY(H20,2),"Mon","Tue","Wed","Thu","Fri","Sat","Sun") -> Sun | J21: Day | K21: =CHOOSE(WEEKDAY(K20,2),"Mon","Tue","Wed","Thu","Fri","Sat","Sun") -> Mon | L21: =CHOOSE(WEEKDAY(L20,2),"Mon","Tue","Wed","Thu","Fri","Sat","Sun") -> Tue | M21: =CHOOSE(WEEKDAY(M20,2),"Mon","Tue","Wed","Thu","Fri","Sat","Sun") -> Wed | N21: =CHOOSE(WEEKDAY(N20,2),"Mon","Tue","Wed","Thu","Fri","Sat","Sun") -> Thu | O21: =CHOOSE(WEEKDAY(O20,2),"Mon","Tue","Wed","Thu","Fri","Sat","Sun") -> Fri | P21: =CHOOSE(WEEKDAY(P20,2),"Mon","Tue","Wed","Thu","Fri","Sat","Sun") -> Sat | Q21: =CHOOSE(WEEKDAY(Q20,2),"Mon","Tue","Wed","Thu","Fri","Sat","Sun") -> Sun | S21: Weekly Goals | T21: Week 3 | U21: Week 4
A22: Exercise | B22: TRUE | C22: TRUE | D22: TRUE | E22: FALSE | F22: TRUE | G22: TRUE | H22: FALSE | J22: Exercise | K22: TRUE | L22: FALSE | M22: FALSE | N22: FALSE | O22: FALSE | P22: FALSE | Q22: FALSE | S22: Laundry | T22: TRUE | U22: TRUE
A23: Stretch/Yoga (>20min) | B23: TRUE | C23: TRUE | D23: FALSE | E23: FALSE | F23: FALSE | G23: TRUE | H23: FALSE | J23: Stretch/Yoga (>20min) | K23: TRUE | L23: FALSE | M23: FALSE | N23: FALSE | O23: FALSE | P23: FALSE | Q23: FALSE | S23: Cleaning | T23: TRUE | U23: TRUE
A24: Social Media (<Limit) | B24: TRUE | C24: TRUE | D24: TRUE | E24: TRUE | F24: TRUE | G24: TRUE | H24: TRUE | J24: Social Media (<Limit) | K24: TRUE | L24: TRUE | M24: TRUE | N24: TRUE | O24: TRUE | P24: TRUE | Q24: TRUE | S24: Grocery Shop | T24: TRUE | U24: TRUE
A25: Eat in | B25: TRUE | C25: TRUE | D25: TRUE | E25: TRUE | F25: TRUE | G25: TRUE | H25: TRUE | J25: Eat in | K25: TRUE | L25: TRUE | M25: TRUE | N25: TRUE | O25: TRUE | P25: FALSE | Q25: TRUE | S25: Meal Prep | T25: TRUE | U25: TRUE
A26: Review Budget/Goals | B26: TRUE | C26: TRUE | D26: TRUE | E26: TRUE | F26: TRUE | G26: TRUE | H26: TRUE | J26: Review Budget/Goals | K26: TRUE | L26: TRUE | M26: TRUE | N26: TRUE | O26: TRUE | P26: TRUE | Q26: TRUE | S26: Website work (~2h) | T26: FALSE | U26: FALSE
A27: Brush Teeth (>=2) | B27: TRUE | C27: TRUE | D27: TRUE | E27: TRUE | F27: TRUE | G27: TRUE | H27: TRUE | J27: (2x)Brush+(1x)Floss | K27: TRUE | L27: FALSE | M27: FALSE | N27: FALSE | O27: FALSE | P27: TRUE | Q27: TRUE | S27: Recycling | T27: TRUE | U27: TRUE
A28: Water (>2.25) | B28: TRUE | C28: TRUE | D28: FALSE | E28: FALSE | F28: FALSE | G28: TRUE | H28: TRUE | J28: Water (>2.25) | K28: TRUE | L28: FALSE | M28: FALSE | N28: FALSE | O28: FALSE | P28: FALSE | Q28: FALSE | S28: Trash | T28: TRUE | U28: TRUE
A29: 7 hours sleep | B29: TRUE | C29: TRUE | D29: FALSE | E29: TRUE | F29: TRUE | G29: FALSE | H29: TRUE | J29: 7 hours sleep | K29: TRUE | L29: FALSE | M29: TRUE | N29: TRUE | O29: TRUE | P29: TRUE | Q29: FALSE | S29: Shave/Trim | T29: TRUE | U29: TRUE
A30: Clean (~20 min) | B30: TRUE | C30: TRUE | D30: FALSE | E30: TRUE | F30: TRUE | G30: TRUE | H30: FALSE | J30: Clean (~20 min) | K30: TRUE | L30: FALSE | M30: FALSE | N30: FALSE | O30: TRUE | P30: TRUE | Q30: FALSE | S30: Water Plants | T30: TRUE | U30: TRUE
A31: Read (~20 min) | B31: TRUE | C31: TRUE | D31: FALSE | E31: FALSE | F31: FALSE | G31: TRUE | H31: FALSE | J31: Read (~20 min) | K31: FALSE | L31: FALSE | M31: FALSE | N31: FALSE | O31: TRUE | P31: FALSE | Q31: FALSE | S31: Weekend Exercise | T31: TRUE | U31: FALSE
A32: Vitamins | B32: TRUE | C32: TRUE | D32: TRUE | E32: TRUE | F32: TRUE | G32: TRUE | H32: TRUE | J32: Vitamins | K32: TRUE | L32: TRUE | M32: FALSE | N32: FALSE | O32: FALSE | P32: TRUE | Q32: TRUE | S32: Total | T32: =COUNTIF(T22:T31,True)/COUNTA(T22:T31) -> 0.9 | U32: =COUNTIF(U22:U31,True)/COUNTA(U22:U31) -> 0.8
A33: Total | B33: =COUNTIF(B22:B32,True)/COUNTA(B22:B32) -> 1 | C33: =COUNTIF(C22:C32,True)/COUNTA(C22:C32) -> 1 | D33: =COUNTIF(D22:D32,True)/COUNTA(D22:D32) -> 0.54545455 | E33: =COUNTIF(E22:E32,True)/COUNTA(E22:E32) -> 0.63636364 | F33: =COUNTIF(F22:F32,True)/COUNTA(F22:F32) -> 0.72727273 | G33: =COUNTIF(G22:G32,True)/COUNTA(G22:G32) -> 0.90909091 | H33: =COUNTIF(H22:H32,True)/COUNTA(H22:H32) -> 0.63636364 | J33: Total | K33: =COUNTIF(K22:K32,True)/COUNTA(K22:K32) -> 0.90909091 | L33: =COUNTIF(L22:L32,True)/COUNTA(L22:L32) -> 0.36363636 | M33: =COUNTIF(M22:M32,True)/COUNTA(M22:M32) -> 0.36363636 | N33: =COUNTIF(N22:N32,True)/COUNTA(N22:N32) -> 0.36363636 | O33: =COUNTIF(O22:O32,True)/COUNTA(O22:O32) -> 0.54545455 | P33: =COUNTIF(P22:P32,True)/COUNTA(P22:P32) -> 0.54545455 | Q33: =COUNTIF(Q22:Q32,True)/COUNTA(Q22:Q32) -> 0.45454545 | S33: Progress bar | T33: =IFERROR(__xludf.DUMMYFUNCTION("SPARKLINE(T32,{""charttype"",""bar"";""max"",1;""min"",0;""color1"",IF(T32>0.7,""green"",IF(T32>0.5,""yellow"",""red""))})"),"") | U33: =IFERROR(__xludf.DUMMYFUNCTION("SPARKLINE(U32,{""charttype"",""bar"";""max"",1;""min"",0;""color1"",IF(U32>0.7,""green"",IF(U32>0.5,""yellow"",""red""))})"),"")
A34: Daily Progress | B34: =IFERROR(__xludf.DUMMYFUNCTION("SPARKLINE(B33,{""charttype"",""bar"";""max"",1;""min"",0;""color1"",IF(B33>0.7,""green"",IF(B33>0.5,""yellow"",""red""))})"),"") | C34: =IFERROR(__xludf.DUMMYFUNCTION("SPARKLINE(C33,{""charttype"",""bar"";""max"",1;""min"",0;""color1"",IF(C33>0.7,""green"",IF(C33>0.5,""yellow"",""red""))})"),"") | D34: =IFERROR(__xludf.DUMMYFUNCTION("SPARKLINE(D33,{""charttype"",""bar"";""max"",1;""min"",0;""color1"",IF(D33>0.7,""green"",IF(D33>0.5,""yellow"",""red""))})"),"") | E34: =IFERROR(__xludf.DUMMYFUNCTION("SPARKLINE(E33,{""charttype"",""bar"";""max"",1;""min"",0;""color1"",IF(E33>0.7,""green"",IF(E33>0.5,""yellow"",""red""))})"),"") | F34: =IFERROR(__xludf.DUMMYFUNCTION("SPARKLINE(F33,{""charttype"",""bar"";""max"",1;""min"",0;""color1"",IF(F33>0.7,""green"",IF(F33>0.5,""yellow"",""red""))})"),"") | G34: =IFERROR(__xludf.DUMMYFUNCTION("SPARKLINE(G33,{""charttype"",""bar"";""max"",1;""min"",0;""color1"",IF(G33>0.7,""green"",IF(G33>0.5,""yellow"",""red""))})"),"") | H34: =IFERROR(__xludf.DUMMYFUNCTION("SPARKLINE(H33,{""charttype"",""bar"";""max"",1;""min"",0;""color1"",IF(H33>0.7,""green"",IF(H33>0.5,""yellow"",""red""))})"),"") | J34: Daily Progress | K34: =IFERROR(__xludf.DUMMYFUNCTION("SPARKLINE(K33,{""charttype"",""bar"";""max"",1;""min"",0;""color1"",IF(K33>0.7,""green"",IF(K33>0.5,""yellow"",""red""))})"),"") | L34: =IFERROR(__xludf.DUMMYFUNCTION("SPARKLINE(L33,{""charttype"",""bar"";""max"",1;""min"",0;""color1"",IF(L33>0.7,""green"",IF(L33>0.5,""yellow"",""red""))})"),"") | M34: =IFERROR(__xludf.DUMMYFUNCTION("SPARKLINE(M33,{""charttype"",""bar"";""max"",1;""min"",0;""color1"",IF(M33>0.7,""green"",IF(M33>0.5,""yellow"",""red""))})"),"") | N34: =IFERROR(__xludf.DUMMYFUNCTION("SPARKLINE(N33,{""charttype"",""bar"";""max"",1;""min"",0;""color1"",IF(N33>0.7,""green"",IF(N33>0.5,""yellow"",""red""))})"),"") | O34: =IFERROR(__xludf.DUMMYFUNCTION("SPARKLINE(O33,{""charttype"",""bar"";""max"",1;""min"",0;""color1"",IF(O33>0.7,""green"",IF(O33>0.5,""yellow"",""red""))})"),"") | P34: =IFERROR(__xludf.DUMMYFUNCTION("SPARKLINE(P33,{""charttype"",""bar"";""max"",1;""min"",0;""color1"",IF(P33>0.7,""green"",IF(P33>0.5,""yellow"",""red""))})"),"") | Q34: =IFERROR(__xludf.DUMMYFUNCTION("SPARKLINE(Q33,{""charttype"",""bar"";""max"",1;""min"",0;""color1"",IF(Q33>0.7,""green"",IF(Q33>0.5,""yellow"",""red""))})"),"")
A35: Weekly Progress | B35: =IFERROR(__xludf.DUMMYFUNCTION("SPARKLINE((SUM(B33:H33)+3*T32)/10,{""charttype"",""bar"";""max"",1;""min"",0;""color1"",IF((SUM(B33:H33)+3*T32)/10>0.7,""green"",IF((SUM(B33:H33)+3*T32)/10>0.5,""yellow"",""red""))})"),"") | J35: Weekly Progress | K35: =IFERROR(__xludf.DUMMYFUNCTION("SPARKLINE((SUM(K33:Q33)+3*U32)/10,{""charttype"",""bar"";""max"",1;""min"",0;""color1"",IF((SUM(K33:Q33)+3*U32)/10>0.7,""green"",IF((SUM(K33:Q33)+3*U32)/10>0.5,""yellow"",""red""))})"),"")

Sheet Dec2022
C1: =IFERROR(__xludf.DUMMYFUNCTION("SPARKLINE((SUM(B16:H16)+3*SUM(T15:U15) + SUM(K16:Q16) + SUM(B33:H33) + SUM(K33:Q33) + 3*SUM(T32:U32)+ 5*SUM(X19))/45,{""charttype"",""bar"";""max"",1;""min"",0;""color1"",IF((SUM(B16:H16)+3*SUM(T15:U15) + SUM(K16:Q16) + SUM(B33:H33) + SUM(K33:Q33) + 3*SUM"&"(T32:U32)+ 5*SUM(X19))/45>0.7,""green"",IF((SUM(B16:H16)+3*SUM(T15:U15) + SUM(K16:Q16) + SUM(B33:H33) + SUM(K33:Q33) + 3*SUM(T32:U32)+ 5*SUM(X19))/45>0.5,""yellow"",""red""))})"),"") | R1: =(SUM(B16:H16)+3*SUM(T15:U15) + SUM(K16:Q16) + SUM(B33:H33) + SUM(K33:Q33) + 3*SUM(T32:U32) + 5*SUM(X19))/45 -> 0.7679798 | S1: Points | T1: {=COUNTIF(B5:H15,TRUE)+COUNTIF(K5:Q15,TRUE)+COUNTIF(B22:H32,TRUE)+COUNTIF(K22:Q32,TRUE)+3*(COUNTIF(T5:U14,TRUE)+COUNTIF(T22:U31,TRUE))+5*(COUNTIF(X15:X18,TRUE))} -> 344 | W1: YTD Points | X1: =T1+'Nov2022'!T1 -> 661
A2: 44896
A3: Week 1 | B3: =DATE(YEAR(A2),MONTH(A2),1)+MOD(9-WEEKDAY(DATE(YEAR(A2),MONTH(A2),1)),7) -> 44900 | C3: =B3+1 -> 44901 | D3: =C3+1 -> 44902 | E3: =D3+1 -> 44903 | F3: =E3+1 -> 44904 | G3: =F3+1 -> 44905 | H3: =G3+1 -> 44906 | J3: Week 2 | K3: =H3+1 -> 44907 | L3: =K3+1 -> 44908 | M3: =L3+1 -> 44909 | N3: =M3+1 -> 44910 | O3: =N3+1 -> 44911 | P3: =O3+1 -> 44912 | Q3: =P3+1 -> 44913
A4: Day | B4: =CHOOSE(WEEKDAY(B3,2),"Mon","Tue","Wed","Thu","Fri","Sat","Sun") -> Mon | C4: =CHOOSE(WEEKDAY(C3,2),"Mon","Tue","Wed","Thu","Fri","Sat","Sun") -> Tue | D4: =CHOOSE(WEEKDAY(D3,2),"Mon","Tue","Wed","Thu","Fri","Sat","Sun") -> Wed | E4: =CHOOSE(WEEKDAY(E3,2),"Mon","Tue","Wed","Thu","Fri","Sat","Sun") -> Thu | F4: =CHOOSE(WEEKDAY(F3,2),"Mon","Tue","Wed","Thu","Fri","Sat","Sun") -> Fri | G4: =CHOOSE(WEEKDAY(G3,2),"Mon","Tue","Wed","Thu","Fri","Sat","Sun") -> Sat | H4: =CHOOSE(WEEKDAY(H3,2),"Mon","Tue","Wed","Thu","Fri","Sat","Sun") -> Sun | J4: Day | K4: =CHOOSE(WEEKDAY(K3,2),"Mon","Tue","Wed","Thu","Fri","Sat","Sun") -> Mon | L4: =CHOOSE(WEEKDAY(L3,2),"Mon","Tue","Wed","Thu","Fri","Sat","Sun") -> Tue | M4: =CHOOSE(WEEKDAY(M3,2),"Mon","Tue","Wed","Thu","Fri","Sat","Sun") -> Wed | N4: =CHOOSE(WEEKDAY(N3,2),"Mon","Tue","Wed","Thu","Fri","Sat","Sun") -> Thu | O4: =CHOOSE(WEEKDAY(O3,2),"Mon","Tue","Wed","Thu","Fri","Sat","Sun") -> Fri | P4: =CHOOSE(WEEKDAY(P3,2),"Mon","Tue","Wed","Thu","Fri","Sat","Sun") -> Sat | Q4: =CHOOSE(WEEKDAY(Q3,2),"Mon","Tue","Wed","Thu","Fri","Sat","Sun") -> Sun | S4: Weekly Goals | T4: Week 1 | U4: Week 2
A5: Exercise | B5: TRUE | C5: TRUE | D5: TRUE | E5: FALSE | F5: TRUE | G5: FALSE | H5: FALSE | J5: =A5 -> Exercise | K5: FALSE | L5: TRUE | M5: TRUE | N5: TRUE | O5: FALSE | P5: FALSE | Q5: FALSE | S5: Laundry | T5: TRUE | U5: TRUE
A6: Stretch/Yoga (>20min) | B6: FALSE | C6: FALSE | D6: FALSE | E6: FALSE | F6: FALSE | G6: FALSE | H6: FALSE | J6: =A6 -> Stretch/Yoga (>20min) | K6: FALSE | L6: TRUE | M6: TRUE | N6: TRUE | O6: FALSE | P6: FALSE | Q6: TRUE | S6: Cleaning | T6: TRUE | U6: FALSE
A7: Social Media (<limit) | B7: TRUE | C7: TRUE | D7: TRUE | E7: TRUE | F7: TRUE | G7: TRUE | H7: TRUE | J7: =A7 -> Social Media (<limit) | K7: TRUE | L7: TRUE | M7: TRUE | N7: TRUE | O7: TRUE | P7: TRUE | Q7: TRUE | S7: Grocery Shop | T7: TRUE | U7: TRUE
A8: Eat in | B8: TRUE | C8: TRUE | D8: FALSE | E8: TRUE | F8: FALSE | G8: TRUE | H8: TRUE | J8: =A8 -> Eat in | K8: FALSE | L8: TRUE | M8: TRUE | N8: TRUE | O8: FALSE | P8: TRUE | Q8: FALSE | S8: Meal Prep | T8: TRUE | U8: FALSE
A9: Review Budget/Goals | B9: TRUE | C9: TRUE | D9: TRUE | E9: TRUE | F9: TRUE | G9: TRUE | H9: TRUE | J9: =A9 -> Review Budget/Goals | K9: TRUE | L9: TRUE | M9: TRUE | N9: TRUE | O9: TRUE | P9: TRUE | Q9: TRUE | S9: Website work (~2h) | T9: FALSE | U9: TRUE
A10: (2x)Brush+(1x)Floss | B10: TRUE | C10: TRUE | D10: TRUE | E10: TRUE | F10: TRUE | G10: TRUE | H10: TRUE | J10: =A10 -> (2x)Brush+(1x)Floss | K10: TRUE | L10: TRUE | M10: TRUE | N10: TRUE | O10: TRUE | P10: TRUE | Q10: TRUE | S10: Recycling | T10: TRUE | U10: TRUE
A11: Water (>2.25L) | B11: TRUE | C11: FALSE | D11: TRUE | E11: TRUE | F11: FALSE | G11: TRUE | H11: TRUE | J11: =A11 -> Water (>2.25L) | K11: TRUE | L11: TRUE | M11: TRUE | N11: TRUE | O11: TRUE | P11: TRUE | Q11: TRUE | S11: Trash | T11: TRUE | U11: TRUE
A12: 7 hours sleep | B12: TRUE | C12: TRUE | D12: TRUE | E12: TRUE | F12: FALSE | G12: TRUE | H12: FALSE | J12: =A12 -> 7 hours sleep | K12: TRUE | L12: TRUE | M12: FALSE | N12: TRUE | O12: TRUE | P12: TRUE | Q12: TRUE | S12: Shave/Trim | T12: TRUE | U12: TRUE
A13: Clean (~20 min) | B13: FALSE | C13: FALSE | D13: TRUE | E13: TRUE | F13: FALSE | G13: TRUE | H13: TRUE | J13: =A13 -> Clean (~20 min) | K13: TRUE | L13: TRUE | M13: TRUE | N13: FALSE | O13: FALSE | P13: FALSE | Q13: TRUE | S13: Water Plants | T13: TRUE | U13: TRUE
A14: Read(~30 min) | B14: FALSE | C14: TRUE | D14: TRUE | E14: TRUE | F14: FALSE | G14: FALSE | H14: FALSE | J14: =A14 -> Read(~30 min) | K14: FALSE | L14: TRUE | M14: FALSE | N14: TRUE | O14: FALSE | P14: FALSE | Q14: FALSE | S14: Weekend Exercise | T14: FALSE | U14: FALSE | W14: Monthly Goals
A15: Vitamins | B15: TRUE | C15: TRUE | D15: TRUE | E15: TRUE | F15: TRUE | G15: TRUE | H15: TRUE | J15: =A15 -> Vitamins | K15: TRUE | L15: TRUE | M15: TRUE | N15: TRUE | O15: TRUE | P15: TRUE | Q15: TRUE | S15: Total | T15: =COUNTIF(T5:T14,True)/COUNTA(T5:T14) -> 0.8 | U15: =COUNTIF(U5:U14,True)/COUNTA(U5:U14) -> 0.7 | W15: Wash Sheets | X15: FALSE
A16: Total | B16: =COUNTIF(B5:B15,True)/COUNTA(B5:B15) -> 0.72727273 | C16: =COUNTIF(C5:C15,True)/COUNTA(C5:C15) -> 0.72727273 | D16: =COUNTIF(D5:D15,True)/COUNTA(D5:D15) -> 0.81818182 | E16: =COUNTIF(E5:E15,True)/COUNTA(E5:E15) -> 0.81818182 | F16: =COUNTIF(F5:F15,True)/COUNTA(F5:F15) -> 0.45454545 | G16: =COUNTIF(G5:G15,True)/COUNTA(G5:G15) -> 0.72727273 | H16: =COUNTIF(H5:H15,True)/COUNTA(H5:H15) -> 0.63636364 | J16: Total | K16: =COUNTIF(K5:K15,True)/COUNTA(K5:K15) -> 0.63636364 | L16: =COUNTIF(L5:L15,True)/COUNTA(L5:L15) -> 1 | M16: =COUNTIF(M5:M15,True)/COUNTA(M5:M15) -> 0.81818182 | N16: =COUNTIF(N5:N15,True)/COUNTA(N5:N15) -> 0.90909091 | O16: =COUNTIF(O5:O15,True)/COUNTA(O5:O15) -> 0.54545455 | P16: =COUNTIF(P5:P15,True)/COUNTA(P5:P15) -> 0.63636364 | Q16: =COUNTIF(Q5:Q15,True)/COUNTA(Q5:Q15) -> 0.72727273 | S16: Progress bar | T16: =IFERROR(__xludf.DUMMYFUNCTION("SPARKLINE(T15,{""charttype"",""bar"";""max"",1;""min"",0;""color1"",IF(T15>0.7,""green"",IF(T15>0.5,""yellow"",""red""))})"),"") | U16: =IFERROR(__xludf.DUMMYFUNCTION("SPARKLINE(U15,{""charttype"",""bar"";""max"",1;""min"",0;""color1"",IF(U15>0.7,""green"",IF(U15>0.5,""yellow"",""red""))})"),"") | W16: Savings Deposit | X16: TRUE
A17: Progress bar | B17: =IFERROR(__xludf.DUMMYFUNCTION("SPARKLINE(B16,{""charttype"",""bar"";""max"",1;""min"",0;""color1"",IF(B16>0.7,""green"",IF(B16>0.5,""yellow"",""red""))})"),"") | C17: =IFERROR(__xludf.DUMMYFUNCTION("SPARKLINE(C16,{""charttype"",""bar"";""max"",1;""min"",0;""color1"",IF(C16>0.7,""green"",IF(C16>0.5,""yellow"",""red""))})"),"") | D17: =IFERROR(__xludf.DUMMYFUNCTION("SPARKLINE(D16,{""charttype"",""bar"";""max"",1;""min"",0;""color1"",IF(D16>0.7,""green"",IF(D16>0.5,""yellow"",""red""))})"),"") | E17: =IFERROR(__xludf.DUMMYFUNCTION("SPARKLINE(E16,{""charttype"",""bar"";""max"",1;""min"",0;""color1"",IF(E16>0.7,""green"",IF(E16>0.5,""yellow"",""red""))})"),"") | F17: =IFERROR(__xludf.DUMMYFUNCTION("SPARKLINE(F16,{""charttype"",""bar"";""max"",1;""min"",0;""color1"",IF(F16>0.7,""green"",IF(F16>0.5,""yellow"",""red""))})"),"") | G17: =IFERROR(__xludf.DUMMYFUNCTION("SPARKLINE(G16,{""charttype"",""bar"";""max"",1;""min"",0;""color1"",IF(G16>0.7,""green"",IF(G16>0.5,""yellow"",""red""))})"),"") | H17: =IFERROR(__xludf.DUMMYFUNCTION("SPARKLINE(H16,{""charttype"",""bar"";""max"",1;""min"",0;""color1"",IF(H16>0.7,""green"",IF(H16>0.5,""yellow"",""red""))})"),"") | J17: Progress bar | K17: =IFERROR(__xludf.DUMMYFUNCTION("SPARKLINE(K16,{""charttype"",""bar"";""max"",1;""min"",0;""color1"",IF(K16>0.7,""green"",IF(K16>0.5,""yellow"",""red""))})"),"") | L17: =IFERROR(__xludf.DUMMYFUNCTION("SPARKLINE(L16,{""charttype"",""bar"";""max"",1;""min"",0;""color1"",IF(L16>0.7,""green"",IF(L16>0.5,""yellow"",""red""))})"),"") | M17: =IFERROR(__xludf.DUMMYFUNCTION("SPARKLINE(M16,{""charttype"",""bar"";""max"",1;""min"",0;""color1"",IF(M16>0.7,""green"",IF(M16>0.5,""yellow"",""red""))})"),"") | N17: =IFERROR(__xludf.DUMMYFUNCTION("SPARKLINE(N16,{""charttype"",""bar"";""max"",1;""min"",0;""color1"",IF(N16>0.7,""green"",IF(N16>0.5,""yellow"",""red""))})"),"") | O17: =IFERROR(__xludf.DUMMYFUNCTION("SPARKLINE(O16,{""charttype"",""bar"";""max"",1;""min"",0;""color1"",IF(O16>0.7,""green"",IF(O16>0.5,""yellow"",""red""))})"),"") | P17: =IFERROR(__xludf.DUMMYFUNCTION("SPARKLINE(P16,{""charttype"",""bar"";""max"",1;""min"",0;""color1"",IF(P16>0.7,""green"",IF(P16>0.5,""yellow"",""red""))})"),"") | Q17: =IFERROR(__xludf.DUMMYFUNCTION("SPARKLINE(Q16,{""charttype"",""bar"";""max"",1;""min"",0;""color1"",IF(Q16>0.7,""green"",IF(Q16>0.5,""yellow"",""red""))})"),"") | W17: Loan Payment | X17: TRUE
A18: Progress bar Total | B18: =IFERROR(__xludf.DUMMYFUNCTION("SPARKLINE((SUM(B16:H16)+3*T15)/10,{""charttype"",""bar"";""max"",1;""min"",0;""color1"",IF((SUM(B16:H16)+3*T15)/10>0.7,""green"",IF((SUM(B16:H16)+3*T15)/10>0.5,""yellow"",""red""))})"),"") | J18: Progress bar Total | K18: =IFERROR(__xludf.DUMMYFUNCTION("SPARKLINE((SUM(K16:Q16)+3*U15)/10,{""charttype"",""bar"";""max"",1;""min"",0;""color1"",IF((SUM(K16:Q16)+3*U15)/10>0.7,""green"",IF((SUM(K16:Q16)+3*U15)/10>0.5,""yellow"",""red""))})"),"") | W18: Wash mats | X18: TRUE
W19: Total | X19: =COUNTIF(X15:X18,True)/COUNTA(X15:X18) -> 0.75
A20: Week 3 | B20: =Q3+1 -> 44914 | C20: =B20+1 -> 44915 | D20: =C20+1 -> 44916 | E20: =D20+1 -> 44917 | F20: =E20+1 -> 44918 | G20: =F20+1 -> 44919 | H20: =G20+1 -> 44920 | J20: Week 4 | K20: =H20+1 -> 44921 | L20: =K20+1 -> 44922 | M20: =L20+1 -> 44923 | N20: =M20+1 -> 44924 | O20: =N20+1 -> 44925 | P20: =O20+1 -> 44926 | Q20: =P20+1 -> 44927 | W20: Progress bar | X20: =IFERROR(__xludf.DUMMYFUNCTION("SPARKLINE(X19,{""charttype"",""bar"";""max"",1;""min"",0;""color1"",IF(X19>0.7,""green"",IF(X19>0.5,""yellow"",""red""))})"),"")
A21: Day | B21: =CHOOSE(WEEKDAY(B20,2),"Mon","Tue","Wed","Thu","Fri","Sat","Sun") -> Mon | C21: =CHOOSE(WEEKDAY(C20,2),"Mon","Tue","Wed","Thu","Fri","Sat","Sun") -> Tue | D21: =CHOOSE(WEEKDAY(D20,2),"Mon","Tue","Wed","Thu","Fri","Sat","Sun") -> Wed | E21: =CHOOSE(WEEKDAY(E20,2),"Mon","Tue","Wed","Thu","Fri","Sat","Sun") -> Thu | F21: =CHOOSE(WEEKDAY(F20,2),"Mon","Tue","Wed","Thu","Fri","Sat","Sun") -> Fri | G21: =CHOOSE(WEEKDAY(G20,2),"Mon","Tue","Wed","Thu","Fri","Sat","Sun") -> Sat | H21: =CHOOSE(WEEKDAY(H20,2),"Mon","Tue","Wed","Thu","Fri","Sat","Sun") -> Sun | J21: Day | K21: =CHOOSE(WEEKDAY(K20,2),"Mon","Tue","Wed","Thu","Fri","Sat","Sun") -> Mon | L21: =CHOOSE(WEEKDAY(L20,2),"Mon","Tue","Wed","Thu","Fri","Sat","Sun") -> Tue | M21: =CHOOSE(WEEKDAY(M20,2),"Mon","Tue","Wed","Thu","Fri","Sat","Sun") -> Wed | N21: =CHOOSE(WEEKDAY(N20,2),"Mon","Tue","Wed","Thu","Fri","Sat","Sun") -> Thu | O21: =CHOOSE(WEEKDAY(O20,2),"Mon","Tue","Wed","Thu","Fri","Sat","Sun") -> Fri | P21: =CHOOSE(WEEKDAY(P20,2),"Mon","Tue","Wed","Thu","Fri","Sat","Sun") -> Sat | Q21: =CHOOSE(WEEKDAY(Q20,2),"Mon","Tue","Wed","Thu","Fri","Sat","Sun") -> Sun | S21: Weekly Goals | T21: Week 3 | U21: Week 4
A22: =A5 -> Exercise | B22: TRUE | C22: TRUE | D22: TRUE | E22: FALSE | F22: TRUE | G22: FALSE | H22: FALSE | J22: =A5 -> Exercise | K22: FALSE | L22: TRUE | M22: TRUE | N22: TRUE | O22: TRUE | P22: FALSE | Q22: TRUE | S22: Laundry | T22: FALSE | U22: TRUE
A23: =A6 -> Stretch/Yoga (>20min) | B23: TRUE | C23: FALSE | D23: TRUE | E23: FALSE | F23: TRUE | G23: TRUE | H23: FALSE | J23: =A6 -> Stretch/Yoga (>20min) | K23: FALSE | L23: TRUE | M23: TRUE | N23: TRUE | O23: TRUE | P23: FALSE | Q23: TRUE | S23: Cleaning | T23: TRUE | U23: TRUE
A24: =A7 -> Social Media (<limit) | B24: TRUE | C24: TRUE | D24: TRUE | E24: TRUE | F24: TRUE | G24: TRUE | H24: TRUE | J24: =A7 -> Social Media (<limit) | K24: TRUE | L24: TRUE | M24: TRUE | N24: TRUE | O24: TRUE | P24: TRUE | Q24: TRUE | S24: Grocery Shop | T24: TRUE | U24: TRUE
A25: =A8 -> Eat in | B25: TRUE | C25: FALSE | D25: FALSE | E25: TRUE | F25: TRUE | G25: TRUE | H25: TRUE | J25: =A8 -> Eat in | K25: FALSE | L25: TRUE | M25: TRUE | N25: TRUE | O25: TRUE | P25: TRUE | Q25: TRUE | S25: Meal Prep | T25: TRUE | U25: TRUE
A26: =A9 -> Review Budget/Goals | B26: TRUE | C26: TRUE | D26: TRUE | E26: TRUE | F26: TRUE | G26: TRUE | H26: TRUE | J26: =A9 -> Review Budget/Goals | K26: TRUE | L26: TRUE | M26: TRUE | N26: TRUE | O26: TRUE | P26: TRUE | Q26: TRUE | S26: Website work (~2h) | T26: TRUE | U26: TRUE
A27: =A10 -> (2x)Brush+(1x)Floss | B27: TRUE | C27: TRUE | D27: TRUE | E27: FALSE | F27: TRUE | G27: FALSE | H27: FALSE | J27: =A10 -> (2x)Brush+(1x)Floss | K27: FALSE | L27: TRUE | M27: TRUE | N27: TRUE | O27: TRUE | P27: FALSE | Q27: FALSE | S27: Recycling | T27: TRUE | U27: TRUE
A28: =A11 -> Water (>2.25L) | B28: TRUE | C28: TRUE | D28: TRUE | E28: FALSE | F28: TRUE | G28: TRUE | H28: TRUE | J28: =A11 -> Water (>2.25L) | K28: FALSE | L28: TRUE | M28: TRUE | N28: TRUE | O28: TRUE | P28: TRUE | Q28: TRUE | S28: Trash | T28: TRUE | U28: TRUE
A29: =A12 -> 7 hours sleep | B29: FALSE | C29: TRUE | D29: TRUE | E29: TRUE | F29: TRUE | G29: TRUE | H29: TRUE | J29: =A12 -> 7 hours sleep | K29: TRUE | L29: TRUE | M29: TRUE | N29: TRUE | O29: FALSE | P29: TRUE | Q29: TRUE | S29: Shave/Trim | T29: TRUE | U29: TRUE
A30: =A13 -> Clean (~20 min) | B30: TRUE | C30: TRUE | D30: TRUE | E30: TRUE | F30: TRUE | G30: FALSE | H30: TRUE | J30: =A13 -> Clean (~20 min) | K30: TRUE | L30: TRUE | M30: TRUE | N30: TRUE | O30: TRUE | P30: TRUE | Q30: TRUE | S30: Water Plants | T30: TRUE | U30: TRUE
A31: =A14 -> Read(~30 min) | B31: FALSE | C31: TRUE | D31: FALSE | E31: FALSE | F31: FALSE | G31: FALSE | H31: FALSE | J31: =A14 -> Read(~30 min) | K31: FALSE | L31: FALSE | M31: FALSE | N31: FALSE | O31: TRUE | P31: FALSE | Q31: FALSE | S31: Weekend Exercise | T31: FALSE | U31: TRUE
A32: =A15 -> Vitamins | B32: TRUE | C32: TRUE | D32: TRUE | E32: TRUE | F32: TRUE | G32: TRUE | H32: TRUE | J32: =A15 -> Vitamins | K32: TRUE | L32: TRUE | M32: TRUE | N32: TRUE | O32: TRUE | P32: TRUE | Q32: TRUE | S32: Total | T32: =COUNTIF(T22:T31,True)/COUNTA(T22:T31) -> 0.8 | U32: =COUNTIF(U22:U31,True)/COUNTA(U22:U31) -> 1
A33: Total | B33: =COUNTIF(B22:B32,True)/COUNTA(B22:B32) -> 0.81818182 | C33: =COUNTIF(C22:C32,True)/COUNTA(C22:C32) -> 0.81818182 | D33: =COUNTIF(D22:D32,True)/COUNTA(D22:D32) -> 0.81818182 | E33: =COUNTIF(E22:E32,True)/COUNTA(E22:E32) -> 0.54545455 | F33: =COUNTIF(F22:F32,True)/COUNTA(F22:F32) -> 0.90909091 | G33: =COUNTIF(G22:G32,True)/COUNTA(G22:G32) -> 0.63636364 | H33: =COUNTIF(H22:H32,True)/COUNTA(H22:H32) -> 0.63636364 | J33: Total | K33: =COUNTIF(K22:K32,True)/COUNTA(K22:K32) -> 0.45454545 | L33: =COUNTIF(L22:L32,True)/COUNTA(L22:L32) -> 0.90909091 | M33: =COUNTIF(M22:M32,True)/COUNTA(M22:M32) -> 0.90909091 | N33: =COUNTIF(N22:N32,True)/COUNTA(N22:N32) -> 0.90909091 | O33: =COUNTIF(O22:O32,True)/COUNTA(O22:O32) -> 0.90909091 | P33: =COUNTIF(P22:P32,True)/COUNTA(P22:P32) -> 0.63636364 | Q33: =COUNTIF(Q22:Q32,True)/COUNTA(Q22:Q32) -> 0.81818182 | S33: Progress bar | T33: =IFERROR(__xludf.DUMMYFUNCTION("SPARKLINE(T32,{""charttype"",""bar"";""max"",1;""min"",0;""color1"",IF(T32>0.7,""green"",IF(T32>0.5,""yellow"",""red""))})"),"") | U33: =IFERROR(__xludf.DUMMYFUNCTION("SPARKLINE(U32,{""charttype"",""bar"";""max"",1;""min"",0;""color1"",IF(U32>0.7,""green"",IF(U32>0.5,""yellow"",""red""))})"),"")
A34: Progress bar | B34: =IFERROR(__xludf.DUMMYFUNCTION("SPARKLINE(B33,{""charttype"",""bar"";""max"",1;""min"",0;""color1"",IF(B33>0.7,""green"",IF(B33>0.5,""yellow"",""red""))})"),"") | C34: =IFERROR(__xludf.DUMMYFUNCTION("SPARKLINE(C33,{""charttype"",""bar"";""max"",1;""min"",0;""color1"",IF(C33>0.7,""green"",IF(C33>0.5,""yellow"",""red""))})"),"") | D34: =IFERROR(__xludf.DUMMYFUNCTION("SPARKLINE(D33,{""charttype"",""bar"";""max"",1;""min"",0;""color1"",IF(D33>0.7,""green"",IF(D33>0.5,""yellow"",""red""))})"),"") | E34: =IFERROR(__xludf.DUMMYFUNCTION("SPARKLINE(E33,{""charttype"",""bar"";""max"",1;""min"",0;""color1"",IF(E33>0.7,""green"",IF(E33>0.5,""yellow"",""red""))})"),"") | F34: =IFERROR(__xludf.DUMMYFUNCTION("SPARKLINE(F33,{""charttype"",""bar"";""max"",1;""min"",0;""color1"",IF(F33>0.7,""green"",IF(F33>0.5,""yellow"",""red""))})"),"") | G34: =IFERROR(__xludf.DUMMYFUNCTION("SPARKLINE(G33,{""charttype"",""bar"";""max"",1;""min"",0;""color1"",IF(G33>0.7,""green"",IF(G33>0.5,""yellow"",""red""))})"),"") | H34: =IFERROR(__xludf.DUMMYFUNCTION("SPARKLINE(H33,{""charttype"",""bar"";""max"",1;""min"",0;""color1"",IF(H33>0.7,""green"",IF(H33>0.5,""yellow"",""red""))})"),"") | J34: Progress bar | K34: =IFERROR(__xludf.DUMMYFUNCTION("SPARKLINE(K33,{""charttype"",""bar"";""max"",1;""min"",0;""color1"",IF(K33>0.7,""green"",IF(K33>0.5,""yellow"",""red""))})"),"") | L34: =IFERROR(__xludf.DUMMYFUNCTION("SPARKLINE(L33,{""charttype"",""bar"";""max"",1;""min"",0;""color1"",IF(L33>0.7,""green"",IF(L33>0.5,""yellow"",""red""))})"),"") | M34: =IFERROR(__xludf.DUMMYFUNCTION("SPARKLINE(M33,{""charttype"",""bar"";""max"",1;""min"",0;""color1"",IF(M33>0.7,""green"",IF(M33>0.5,""yellow"",""red""))})"),"") | N34: =IFERROR(__xludf.DUMMYFUNCTION("SPARKLINE(N33,{""charttype"",""bar"";""max"",1;""min"",0;""color1"",IF(N33>0.7,""green"",IF(N33>0.5,""yellow"",""red""))})"),"") | O34: =IFERROR(__xludf.DUMMYFUNCTION("SPARKLINE(O33,{""charttype"",""bar"";""max"",1;""min"",0;""color1"",IF(O33>0.7,""green"",IF(O33>0.5,""yellow"",""red""))})"),"") | P34: =IFERROR(__xludf.DUMMYFUNCTION("SPARKLINE(P33,{""charttype"",""bar"";""max"",1;""min"",0;""color1"",IF(P33>0.7,""green"",IF(P33>0.5,""yellow"",""red""))})"),"") | Q34: =IFERROR(__xludf.DUMMYFUNCTION("SPARKLINE(Q33,{""charttype"",""bar"";""max"",1;""min"",0;""color1"",IF(Q33>0.7,""green"",IF(Q33>0.5,""yellow"",""red""))})"),"")
A35: Progress bar Total | B35: =IFERROR(__xludf.DUMMYFUNCTION("SPARKLINE((SUM(B33:H33)+3*T32)/10,{""charttype"",""bar"";""max"",1;""min"",0;""color1"",IF((SUM(B33:H33)+3*T32)/10>0.7,""green"",IF((SUM(B33:H33)+3*T32)/10>0.5,""yellow"",""red""))})"),"") | J35: Progress bar Total | K35: =IFERROR(__xludf.DUMMYFUNCTION("SPARKLINE((SUM(K33:Q33)+3*U32)/10,{""charttype"",""bar"";""max"",1;""min"",0;""color1"",IF((SUM(K33:Q33)+3*U32)/10>0.7,""green"",IF((SUM(K33:Q33)+3*U32)/10>0.5,""yellow"",""red""))})"),"")

Sheet Jan2023
C1: =IFERROR(__xludf.DUMMYFUNCTION("SPARKLINE((SUM(B16:H16)+3*SUM(T15:U15) + SUM(K16:Q16) + SUM(B33:H33) + SUM(K33:Q33) + 3*SUM(T32:U32)+ 5*SUM(X19))/45,{""charttype"",""bar"";""max"",1;""min"",0;""color1"",IF((SUM(B16:H16)+3*SUM(T15:U15) + SUM(K16:Q16) + SUM(B33:H33) + SUM(K33:Q33) + 3*SUM"&"(T32:U32)+ 5*SUM(X19))/45>0.7,""green"",IF((SUM(B16:H16)+3*SUM(T15:U15) + SUM(K16:Q16) + SUM(B33:H33) + SUM(K33:Q33) + 3*SUM(T32:U32)+ 5*SUM(X19))/45>0.5,""yellow"",""red""))})"),"") | R1: =(SUM(B16:H16)+3*SUM(T15:U15) + SUM(K16:Q16) + SUM(B33:H33) + SUM(K33:Q33) + 3*SUM(T32:U32) + 5*SUM(X19))/45 -> 0.70383838 | S1: Points | T1: {=COUNTIF(B5:H15,TRUE)+COUNTIF(K5:Q15,TRUE)+COUNTIF(B22:H32,TRUE)+COUNTIF(K22:Q32,TRUE)+3*(COUNTIF(T5:U14,TRUE)+COUNTIF(T22:U31,TRUE))+5*(COUNTIF(X15:X18,TRUE))} -> 305 | W1: YTD Points | X1: =T1 -> 305
A2: 44927
A3: Week 1 | B3: =DATE(YEAR(A2),MONTH(A2),1)+MOD(9-WEEKDAY(DATE(YEAR(A2),MONTH(A2),1)),7) -> 44928 | C3: =B3+1 -> 44929 | D3: =C3+1 -> 44930 | E3: =D3+1 -> 44931 | F3: =E3+1 -> 44932 | G3: =F3+1 -> 44933 | H3: =G3+1 -> 44934 | J3: Week 2 | K3: =H3+1 -> 44935 | L3: =K3+1 -> 44936 | M3: =L3+1 -> 44937 | N3: =M3+1 -> 44938 | O3: =N3+1 -> 44939 | P3: =O3+1 -> 44940 | Q3: =P3+1 -> 44941
A4: Day | B4: =CHOOSE(WEEKDAY(B3,2),"Mon","Tue","Wed","Thu","Fri","Sat","Sun") -> Mon | C4: =CHOOSE(WEEKDAY(C3,2),"Mon","Tue","Wed","Thu","Fri","Sat","Sun") -> Tue | D4: =CHOOSE(WEEKDAY(D3,2),"Mon","Tue","Wed","Thu","Fri","Sat","Sun") -> Wed | E4: =CHOOSE(WEEKDAY(E3,2),"Mon","Tue","Wed","Thu","Fri","Sat","Sun") -> Thu | F4: =CHOOSE(WEEKDAY(F3,2),"Mon","Tue","Wed","Thu","Fri","Sat","Sun") -> Fri | G4: =CHOOSE(WEEKDAY(G3,2),"Mon","Tue","Wed","Thu","Fri","Sat","Sun") -> Sat | H4: =CHOOSE(WEEKDAY(H3,2),"Mon","Tue","Wed","Thu","Fri","Sat","Sun") -> Sun | J4: Day | K4: =CHOOSE(WEEKDAY(K3,2),"Mon","Tue","Wed","Thu","Fri","Sat","Sun") -> Mon | L4: =CHOOSE(WEEKDAY(L3,2),"Mon","Tue","Wed","Thu","Fri","Sat","Sun") -> Tue | M4: =CHOOSE(WEEKDAY(M3,2),"Mon","Tue","Wed","Thu","Fri","Sat","Sun") -> Wed | N4: =CHOOSE(WEEKDAY(N3,2),"Mon","Tue","Wed","Thu","Fri","Sat","Sun") -> Thu | O4: =CHOOSE(WEEKDAY(O3,2),"Mon","Tue","Wed","Thu","Fri","Sat","Sun") -> Fri | P4: =CHOOSE(WEEKDAY(P3,2),"Mon","Tue","Wed","Thu","Fri","Sat","Sun") -> Sat | Q4: =CHOOSE(WEEKDAY(Q3,2),"Mon","Tue","Wed","Thu","Fri","Sat","Sun") -> Sun | S4: Weekly Goals | T4: Week 1 | U4: Week 2
A5: Exercise | B5: TRUE | C5: TRUE | D5: TRUE | E5: TRUE | F5: TRUE | G5: FALSE | H5: TRUE | J5: =A5 -> Exercise | K5: TRUE | L5: TRUE | M5: FALSE | N5: FALSE | O5: FALSE | P5: FALSE | Q5: FALSE | S5: Laundry | T5: TRUE | U5: TRUE
A6: Stretch/Yoga (>20min) | B6: FALSE | C6: TRUE | D6: FALSE | E6: TRUE | F6: FALSE | G6: FALSE | H6: FALSE | J6: =A6 -> Stretch/Yoga (>20min) | K6: FALSE | L6: FALSE | M6: TRUE | N6: FALSE | O6: FALSE | P6: FALSE | Q6: FALSE | S6: Cleaning | T6: TRUE | U6: TRUE
A7: Social Media (<limit) | B7: TRUE | C7: TRUE | D7: TRUE | E7: TRUE | F7: TRUE | G7: TRUE | H7: TRUE | J7: =A7 -> Social Media (<limit) | K7: TRUE | L7: TRUE | M7: TRUE | N7: TRUE | O7: TRUE | P7: TRUE | Q7: FALSE | S7: Grocery Shop | T7: TRUE | U7: FALSE
A8: Eat in | B8: TRUE | C8: TRUE | D8: TRUE | E8: TRUE | F8: TRUE | G8: TRUE | H8: TRUE | J8: =A8 -> Eat in | K8: TRUE | L8: TRUE | M8: TRUE | N8: FALSE | O8: FALSE | P8: FALSE | Q8: FALSE | S8: Meal Prep | T8: TRUE | U8: FALSE
A9: Review Budget/Goals | B9: TRUE | C9: TRUE | D9: TRUE | E9: TRUE | F9: TRUE | G9: TRUE | H9: TRUE | J9: =A9 -> Review Budget/Goals | K9: TRUE | L9: TRUE | M9: TRUE | N9: TRUE | O9: TRUE | P9: TRUE | Q9: TRUE | S9: Website work (~2h) | T9: FALSE | U9: FALSE
A10: (2x)Brush+(1x)Floss | B10: TRUE | C10: TRUE | D10: TRUE | E10: TRUE | F10: FALSE | G10: FALSE | H10: TRUE | J10: =A10 -> (2x)Brush+(1x)Floss | K10: TRUE | L10: TRUE | M10: FALSE | N10: FALSE | O10: FALSE | P10: FALSE | Q10: FALSE | S10: Recycling | T10: TRUE | U10: FALSE
A11: Water (~2.25L+) | B11: FALSE | C11: TRUE | D11: TRUE | E11: TRUE | F11: TRUE | G11: TRUE | H11: TRUE | J11: =A11 -> Water (~2.25L+) | K11: TRUE | L11: TRUE | M11: TRUE | N11: FALSE | O11: FALSE | P11: FALSE | Q11: FALSE | S11: Trash | T11: TRUE | U11: FALSE
A12: Sleep (~7 hours+) | B12: TRUE | C12: FALSE | D12: FALSE | E12: FALSE | F12: FALSE | G12: TRUE | H12: FALSE | J12: =A12 -> Sleep (~7 hours+) | K12: FALSE | L12: FALSE | M12: TRUE | N12: TRUE | O12: TRUE | P12: TRUE | Q12: TRUE | S12: Shave/Trim | T12: TRUE | U12: TRUE
A13: Clean (~20 min) | B13: TRUE | C13: TRUE | D13: TRUE | E13: TRUE | F13: FALSE | G13: FALSE | H13: TRUE | J13: =A13 -> Clean (~20 min) | K13: TRUE | L13: FALSE | M13: TRUE | N13: FALSE | O13: FALSE | P13: FALSE | Q13: FALSE | S13: Water Plants | T13: TRUE | U13: FALSE
A14: Read (~20 min) | B14: FALSE | C14: FALSE | D14: FALSE | E14: FALSE | F14: TRUE | G14: FALSE | H14: FALSE | J14: =A14 -> Read (~20 min) | K14: FALSE | L14: FALSE | M14: FALSE | N14: FALSE | O14: FALSE | P14: FALSE | Q14: FALSE | S14: Weekend Exercise | T14: FALSE | U14: FALSE | W14: Monthly Goals
A15: Vitamins | B15: TRUE | C15: TRUE | D15: TRUE | E15: TRUE | F15: TRUE | G15: TRUE | H15: TRUE | J15: =A15 -> Vitamins | K15: TRUE | L15: TRUE | M15: TRUE | N15: FALSE | O15: FALSE | P15: FALSE | Q15: FALSE | S15: Total | T15: =COUNTIF(T5:T14,True)/COUNTA(T5:T14) -> 0.8 | U15: =COUNTIF(U5:U14,True)/COUNTA(U5:U14) -> 0.3 | W15: Wash Sheets | X15: TRUE
A16: Total | B16: =COUNTIF(B5:B15,True)/COUNTA(B5:B15) -> 0.72727273 | C16: =COUNTIF(C5:C15,True)/COUNTA(C5:C15) -> 0.81818182 | D16: =COUNTIF(D5:D15,True)/COUNTA(D5:D15) -> 0.72727273 | E16: =COUNTIF(E5:E15,True)/COUNTA(E5:E15) -> 0.81818182 | F16: =COUNTIF(F5:F15,True)/COUNTA(F5:F15) -> 0.63636364 | G16: =COUNTIF(G5:G15,True)/COUNTA(G5:G15) -> 0.54545455 | H16: =COUNTIF(H5:H15,True)/COUNTA(H5:H15) -> 0.72727273 | J16: Total | K16: =COUNTIF(K5:K15,True)/COUNTA(K5:K15) -> 0.72727273 | L16: =COUNTIF(L5:L15,True)/COUNTA(L5:L15) -> 0.63636364 | M16: =COUNTIF(M5:M15,True)/COUNTA(M5:M15) -> 0.72727273 | N16: =COUNTIF(N5:N15,True)/COUNTA(N5:N15) -> 0.27272727 | O16: =COUNTIF(O5:O15,True)/COUNTA(O5:O15) -> 0.27272727 | P16: =COUNTIF(P5:P15,True)/COUNTA(P5:P15) -> 0.27272727 | Q16: =COUNTIF(Q5:Q15,True)/COUNTA(Q5:Q15) -> 0.18181818 | S16: Progress bar | T16: =IFERROR(__xludf.DUMMYFUNCTION("SPARKLINE(T15,{""charttype"",""bar"";""max"",1;""min"",0;""color1"",IF(T15>0.7,""green"",IF(T15>0.5,""yellow"",""red""))})"),"") | U16: =IFERROR(__xludf.DUMMYFUNCTION("SPARKLINE(U15,{""charttype"",""bar"";""max"",1;""min"",0;""color1"",IF(U15>0.7,""green"",IF(U15>0.5,""yellow"",""red""))})"),"") | W16: Savings Deposit | X16: TRUE
A17: Progress bar | B17: =IFERROR(__xludf.DUMMYFUNCTION("SPARKLINE(B16,{""charttype"",""bar"";""max"",1;""min"",0;""color1"",IF(B16>0.7,""green"",IF(B16>0.5,""yellow"",""red""))})"),"") | C17: =IFERROR(__xludf.DUMMYFUNCTION("SPARKLINE(C16,{""charttype"",""bar"";""max"",1;""min"",0;""color1"",IF(C16>0.7,""green"",IF(C16>0.5,""yellow"",""red""))})"),"") | D17: =IFERROR(__xludf.DUMMYFUNCTION("SPARKLINE(D16,{""charttype"",""bar"";""max"",1;""min"",0;""color1"",IF(D16>0.7,""green"",IF(D16>0.5,""yellow"",""red""))})"),"") | E17: =IFERROR(__xludf.DUMMYFUNCTION("SPARKLINE(E16,{""charttype"",""bar"";""max"",1;""min"",0;""color1"",IF(E16>0.7,""green"",IF(E16>0.5,""yellow"",""red""))})"),"") | F17: =IFERROR(__xludf.DUMMYFUNCTION("SPARKLINE(F16,{""charttype"",""bar"";""max"",1;""min"",0;""color1"",IF(F16>0.7,""green"",IF(F16>0.5,""yellow"",""red""))})"),"") | G17: =IFERROR(__xludf.DUMMYFUNCTION("SPARKLINE(G16,{""charttype"",""bar"";""max"",1;""min"",0;""color1"",IF(G16>0.7,""green"",IF(G16>0.5,""yellow"",""red""))})"),"") | H17: =IFERROR(__xludf.DUMMYFUNCTION("SPARKLINE(H16,{""charttype"",""bar"";""max"",1;""min"",0;""color1"",IF(H16>0.7,""green"",IF(H16>0.5,""yellow"",""red""))})"),"") | J17: Progress bar | K17: =IFERROR(__xludf.DUMMYFUNCTION("SPARKLINE(K16,{""charttype"",""bar"";""max"",1;""min"",0;""color1"",IF(K16>0.7,""green"",IF(K16>0.5,""yellow"",""red""))})"),"") | L17: =IFERROR(__xludf.DUMMYFUNCTION("SPARKLINE(L16,{""charttype"",""bar"";""max"",1;""min"",0;""color1"",IF(L16>0.7,""green"",IF(L16>0.5,""yellow"",""red""))})"),"") | M17: =IFERROR(__xludf.DUMMYFUNCTION("SPARKLINE(M16,{""charttype"",""bar"";""max"",1;""min"",0;""color1"",IF(M16>0.7,""green"",IF(M16>0.5,""yellow"",""red""))})"),"") | N17: =IFERROR(__xludf.DUMMYFUNCTION("SPARKLINE(N16,{""charttype"",""bar"";""max"",1;""min"",0;""color1"",IF(N16>0.7,""green"",IF(N16>0.5,""yellow"",""red""))})"),"") | O17: =IFERROR(__xludf.DUMMYFUNCTION("SPARKLINE(O16,{""charttype"",""bar"";""max"",1;""min"",0;""color1"",IF(O16>0.7,""green"",IF(O16>0.5,""yellow"",""red""))})"),"") | P17: =IFERROR(__xludf.DUMMYFUNCTION("SPARKLINE(P16,{""charttype"",""bar"";""max"",1;""min"",0;""color1"",IF(P16>0.7,""green"",IF(P16>0.5,""yellow"",""red""))})"),"") | Q17: =IFERROR(__xludf.DUMMYFUNCTION("SPARKLINE(Q16,{""charttype"",""bar"";""max"",1;""min"",0;""color1"",IF(Q16>0.7,""green"",IF(Q16>0.5,""yellow"",""red""))})"),"") | W17: Loan Payment | X17: TRUE
A18: Progress bar Total | B18: =IFERROR(__xludf.DUMMYFUNCTION("SPARKLINE((SUM(B16:H16)+3*T15)/10,{""charttype"",""bar"";""max"",1;""min"",0;""color1"",IF((SUM(B16:H16)+3*T15)/10>0.7,""green"",IF((SUM(B16:H16)+3*T15)/10>0.5,""yellow"",""red""))})"),"") | J18: Progress bar Total | K18: =IFERROR(__xludf.DUMMYFUNCTION("SPARKLINE((SUM(K16:Q16)+3*U15)/10,{""charttype"",""bar"";""max"",1;""min"",0;""color1"",IF((SUM(K16:Q16)+3*U15)/10>0.7,""green"",IF((SUM(K16:Q16)+3*U15)/10>0.5,""yellow"",""red""))})"),"") | W18: Wash mats | X18: TRUE
W19: Total | X19: =COUNTIF(X15:X18,True)/COUNTA(X15:X18) -> 1
A20: Week 3 | B20: =Q3+1 -> 44942 | C20: =B20+1 -> 44943 | D20: =C20+1 -> 44944 | E20: =D20+1 -> 44945 | F20: =E20+1 -> 44946 | G20: =F20+1 -> 44947 | H20: =G20+1 -> 44948 | J20: Week 4 | K20: =H20+1 -> 44949 | L20: =K20+1 -> 44950 | M20: =L20+1 -> 44951 | N20: =M20+1 -> 44952 | O20: =N20+1 -> 44953 | P20: =O20+1 -> 44954 | Q20: =P20+1 -> 44955 | W20: Progress bar | X20: =IFERROR(__xludf.DUMMYFUNCTION("SPARKLINE(X19,{""charttype"",""bar"";""max"",1;""min"",0;""color1"",IF(X19>0.7,""green"",IF(X19>0.5,""yellow"",""red""))})"),"")
A21: Day | B21: =CHOOSE(WEEKDAY(B20,2),"Mon","Tue","Wed","Thu","Fri","Sat","Sun") -> Mon | C21: =CHOOSE(WEEKDAY(C20,2),"Mon","Tue","Wed","Thu","Fri","Sat","Sun") -> Tue | D21: =CHOOSE(WEEKDAY(D20,2),"Mon","Tue","Wed","Thu","Fri","Sat","Sun") -> Wed | E21: =CHOOSE(WEEKDAY(E20,2),"Mon","Tue","Wed","Thu","Fri","Sat","Sun") -> Thu | F21: =CHOOSE(WEEKDAY(F20,2),"Mon","Tue","Wed","Thu","Fri","Sat","Sun") -> Fri | G21: =CHOOSE(WEEKDAY(G20,2),"Mon","Tue","Wed","Thu","Fri","Sat","Sun") -> Sat | H21: =CHOOSE(WEEKDAY(H20,2),"Mon","Tue","Wed","Thu","Fri","Sat","Sun") -> Sun | J21: Day | K21: =CHOOSE(WEEKDAY(K20,2),"Mon","Tue","Wed","Thu","Fri","Sat","Sun") -> Mon | L21: =CHOOSE(WEEKDAY(L20,2),"Mon","Tue","Wed","Thu","Fri","Sat","Sun") -> Tue | M21: =CHOOSE(WEEKDAY(M20,2),"Mon","Tue","Wed","Thu","Fri","Sat","Sun") -> Wed | N21: =CHOOSE(WEEKDAY(N20,2),"Mon","Tue","Wed","Thu","Fri","Sat","Sun") -> Thu | O21: =CHOOSE(WEEKDAY(O20,2),"Mon","Tue","Wed","Thu","Fri","Sat","Sun") -> Fri | P21: =CHOOSE(WEEKDAY(P20,2),"Mon","Tue","Wed","Thu","Fri","Sat","Sun") -> Sat | Q21: =CHOOSE(WEEKDAY(Q20,2),"Mon","Tue","Wed","Thu","Fri","Sat","Sun") -> Sun | S21: Weekly Goals | T21: Week 3 | U21: Week 4
A22: =A5 -> Exercise | B22: FALSE | C22: TRUE | D22: FALSE | E22: FALSE | F22: FALSE | G22: FALSE | H22: FALSE | J22: =A5 -> Exercise | K22: FALSE | L22: FALSE | M22: FALSE | N22: TRUE | O22: TRUE | P22: FALSE | Q22: TRUE | S22: Laundry | T22: TRUE | U22: TRUE
A23: =A6 -> Stretch/Yoga (>20min) | B23: FALSE | C23: TRUE | D23: FALSE | E23: TRUE | F23: FALSE | G23: FALSE | H23: FALSE | J23: =A6 -> Stretch/Yoga (>20min) | K23: FALSE | L23: TRUE | M23: FALSE | N23: TRUE | O23: TRUE | P23: FALSE | Q23: TRUE | S23: Cleaning | T23: TRUE | U23: TRUE
A24: =A7 -> Social Media (<limit) | B24: FALSE | C24: FALSE | D24: TRUE | E24: TRUE | F24: TRUE | G24: TRUE | H24: TRUE | J24: =A7 -> Social Media (<limit) | K24: TRUE | L24: TRUE | M24: TRUE | N24: TRUE | O24: TRUE | P24: TRUE | Q24: TRUE | S24: Grocery Shop | T24: TRUE | U24: TRUE
A25: =A8 -> Eat in | B25: FALSE | C25: FALSE | D25: FALSE | E25: TRUE | F25: TRUE | G25: TRUE | H25: TRUE | J25: =A8 -> Eat in | K25: TRUE | L25: TRUE | M25: TRUE | N25: TRUE | O25: TRUE | P25: TRUE | Q25: TRUE | S25: Meal Prep | T25: TRUE | U25: TRUE
A26: =A9 -> Review Budget/Goals | B26: TRUE | C26: TRUE | D26: TRUE | E26: TRUE | F26: TRUE | G26: TRUE | H26: TRUE | J26: =A9 -> Review Budget/Goals | K26: TRUE | L26: TRUE | M26: TRUE | N26: TRUE | O26: TRUE | P26: TRUE | Q26: TRUE | S26: Website work (~2h) | T26: FALSE | U26: FALSE
A27: =A10 -> (2x)Brush+(1x)Floss | B27: FALSE | C27: TRUE | D27: TRUE | E27: TRUE | F27: FALSE | G27: FALSE | H27: TRUE | J27: =A10 -> (2x)Brush+(1x)Floss | K27: TRUE | L27: TRUE | M27: TRUE | N27: TRUE | O27: TRUE | P27: FALSE | Q27: TRUE | S27: Recycling | T27: TRUE | U27: TRUE
A28: =A11 -> Water (~2.25L+) | B28: FALSE | C28: TRUE | D28: FALSE | E28: FALSE | F28: FALSE | G28: TRUE | H28: TRUE | J28: =A11 -> Water (~2.25L+) | K28: TRUE | L28: FALSE | M28: TRUE | N28: TRUE | O28: TRUE | P28: TRUE | Q28: TRUE | S28: Trash | T28: TRUE | U28: TRUE
A29: =A12 -> Sleep (~7 hours+) | B29: TRUE | C29: TRUE | D29: TRUE | E29: TRUE | F29: TRUE | G29: TRUE | H29: TRUE | J29: =A12 -> Sleep (~7 hours+) | K29: TRUE | L29: TRUE | M29: TRUE | N29: TRUE | O29: TRUE | P29: TRUE | Q29: TRUE | S29: Shave/Trim | T29: TRUE | U29: TRUE
A30: =A13 -> Clean (~20 min) | B30: FALSE | C30: TRUE | D30: FALSE | E30: TRUE | F30: TRUE | G30: TRUE | H30: TRUE | J30: =A13 -> Clean (~20 min) | K30: FALSE | L30: FALSE | M30: FALSE | N30: TRUE | O30: TRUE | P30: TRUE | Q30: TRUE | S30: Water Plants | T30: TRUE | U30: TRUE
A31: =A14 -> Read (~20 min) | B31: FALSE | C31: FALSE | D31: TRUE | E31: TRUE | F31: FALSE | G31: FALSE | H31: TRUE | J31: =A14 -> Read (~20 min) | K31: TRUE | L31: TRUE | M31: TRUE | N31: TRUE | O31: TRUE | P31: TRUE | Q31: TRUE | S31: Weekend Exercise | T31: FALSE | U31: TRUE
A32: =A15 -> Vitamins | B32: TRUE | C32: TRUE | D32: FALSE | E32: TRUE | F32: TRUE | G32: TRUE | H32: TRUE | J32: =A15 -> Vitamins | K32: TRUE | L32: TRUE | M32: TRUE | N32: TRUE | O32: TRUE | P32: TRUE | Q32: TRUE | S32: Total | T32: =COUNTIF(T22:T31,True)/COUNTA(T22:T31) -> 0.8 | U32: =COUNTIF(U22:U31,True)/COUNTA(U22:U31) -> 0.9
A33: Total | B33: =COUNTIF(B22:B32,True)/COUNTA(B22:B32) -> 0.27272727 | C33: =COUNTIF(C22:C32,True)/COUNTA(C22:C32) -> 0.72727273 | D33: =COUNTIF(D22:D32,True)/COUNTA(D22:D32) -> 0.45454545 | E33: =COUNTIF(E22:E32,True)/COUNTA(E22:E32) -> 0.81818182 | F33: =COUNTIF(F22:F32,True)/COUNTA(F22:F32) -> 0.54545455 | G33: =COUNTIF(G22:G32,True)/COUNTA(G22:G32) -> 0.63636364 | H33: =COUNTIF(H22:H32,True)/COUNTA(H22:H32) -> 0.81818182 | J33: Total | K33: =COUNTIF(K22:K32,True)/COUNTA(K22:K32) -> 0.72727273 | L33: =COUNTIF(L22:L32,True)/COUNTA(L22:L32) -> 0.72727273 | M33: =COUNTIF(M22:M32,True)/COUNTA(M22:M32) -> 0.72727273 | N33: =COUNTIF(N22:N32,True)/COUNTA(N22:N32) -> 1 | O33: =COUNTIF(O22:O32,True)/COUNTA(O22:O32) -> 1 | P33: =COUNTIF(P22:P32,True)/COUNTA(P22:P32) -> 0.72727273 | Q33: =COUNTIF(Q22:Q32,True)/COUNTA(Q22:Q32) -> 1 | S33: Progress bar | T33: =IFERROR(__xludf.DUMMYFUNCTION("SPARKLINE(T32,{""charttype"",""bar"";""max"",1;""min"",0;""color1"",IF(T32>0.7,""green"",IF(T32>0.5,""yellow"",""red""))})"),"") | U33: =IFERROR(__xludf.DUMMYFUNCTION("SPARKLINE(U32,{""charttype"",""bar"";""max"",1;""min"",0;""color1"",IF(U32>0.7,""green"",IF(U32>0.5,""yellow"",""red""))})"),"")
A34: Progress bar | B34: =IFERROR(__xludf.DUMMYFUNCTION("SPARKLINE(B33,{""charttype"",""bar"";""max"",1;""min"",0;""color1"",IF(B33>0.7,""green"",IF(B33>0.5,""yellow"",""red""))})"),"") | C34: =IFERROR(__xludf.DUMMYFUNCTION("SPARKLINE(C33,{""charttype"",""bar"";""max"",1;""min"",0;""color1"",IF(C33>0.7,""green"",IF(C33>0.5,""yellow"",""red""))})"),"") | D34: =IFERROR(__xludf.DUMMYFUNCTION("SPARKLINE(D33,{""charttype"",""bar"";""max"",1;""min"",0;""color1"",IF(D33>0.7,""green"",IF(D33>0.5,""yellow"",""red""))})"),"") | E34: =IFERROR(__xludf.DUMMYFUNCTION("SPARKLINE(E33,{""charttype"",""bar"";""max"",1;""min"",0;""color1"",IF(E33>0.7,""green"",IF(E33>0.5,""yellow"",""red""))})"),"") | F34: =IFERROR(__xludf.DUMMYFUNCTION("SPARKLINE(F33,{""charttype"",""bar"";""max"",1;""min"",0;""color1"",IF(F33>0.7,""green"",IF(F33>0.5,""yellow"",""red""))})"),"") | G34: =IFERROR(__xludf.DUMMYFUNCTION("SPARKLINE(G33,{""charttype"",""bar"";""max"",1;""min"",0;""color1"",IF(G33>0.7,""green"",IF(G33>0.5,""yellow"",""red""))})"),"") | H34: =IFERROR(__xludf.DUMMYFUNCTION("SPARKLINE(H33,{""charttype"",""bar"";""max"",1;""min"",0;""color1"",IF(H33>0.7,""green"",IF(H33>0.5,""yellow"",""red""))})"),"") | J34: Progress bar | K34: =IFERROR(__xludf.DUMMYFUNCTION("SPARKLINE(K33,{""charttype"",""bar"";""max"",1;""min"",0;""color1"",IF(K33>0.7,""green"",IF(K33>0.5,""yellow"",""red""))})"),"") | L34: =IFERROR(__xludf.DUMMYFUNCTION("SPARKLINE(L33,{""charttype"",""bar"";""max"",1;""min"",0;""color1"",IF(L33>0.7,""green"",IF(L33>0.5,""yellow"",""red""))})"),"") | M34: =IFERROR(__xludf.DUMMYFUNCTION("SPARKLINE(M33,{""charttype"",""bar"";""max"",1;""min"",0;""color1"",IF(M33>0.7,""green"",IF(M33>0.5,""yellow"",""red""))})"),"") | N34: =IFERROR(__xludf.DUMMYFUNCTION("SPARKLINE(N33,{""charttype"",""bar"";""max"",1;""min"",0;""color1"",IF(N33>0.7,""green"",IF(N33>0.5,""yellow"",""red""))})"),"") | O34: =IFERROR(__xludf.DUMMYFUNCTION("SPARKLINE(O33,{""charttype"",""bar"";""max"",1;""min"",0;""color1"",IF(O33>0.7,""green"",IF(O33>0.5,""yellow"",""red""))})"),"") | P34: =IFERROR(__xludf.DUMMYFUNCTION("SPARKLINE(P33,{""charttype"",""bar"";""max"",1;""min"",0;""color1"",IF(P33>0.7,""green"",IF(P33>0.5,""yellow"",""red""))})"),"") | Q34: =IFERROR(__xludf.DUMMYFUNCTION("SPARKLINE(Q33,{""charttype"",""bar"";""max"",1;""min"",0;""color1"",IF(Q33>0.7,""green"",IF(Q33>0.5,""yellow"",""red""))})"),"")
A35: Progress bar Total | B35: =IFERROR(__xludf.DUMMYFUNCTION("SPARKLINE((SUM(B33:H33)+3*T32)/10,{""charttype"",""bar"";""max"",1;""min"",0;""color1"",IF((SUM(B33:H33)+3*T32)/10>0.7,""green"",IF((SUM(B33:H33)+3*T32)/10>0.5,""yellow"",""red""))})"),"") | J35: Progress bar Total | K35: =IFERROR(__xludf.DUMMYFUNCTION("SPARKLINE((SUM(K33:Q33)+3*U32)/10,{""charttype"",""bar"";""max"",1;""min"",0;""color1"",IF((SUM(K33:Q33)+3*U32)/10>0.7,""green"",IF((SUM(K33:Q33)+3*U32)/10>0.5,""yellow"",""red""))})"),"")

Sheet Feb2023
D2: =IFERROR(__xludf.DUMMYFUNCTION("SPARKLINE((SUM(C19:I19)+3*SUM(U19:V19) + SUM(L19:R19) + SUM(C37:I37) + SUM(L37:R37) + 3*SUM(U34:V34)+ 5*SUM(Y22))/45,{""charttype"",""bar"";""max"",1;""min"",0;""color1"",IF((SUM(C19:I19)+3*SUM(U19:V19) + SUM(L19:R19) + SUM(C37:I37) + SUM(L37:R37) + 3*SUM"&"(U34:V34)+ 5*SUM(Y22))/45>0.7,""green"",IF((SUM(C19:I19)+3*SUM(U19:V19) + SUM(L19:R19) + SUM(C37:I37) + SUM(L37:R37) + 3*SUM(U34:V34)+ 5*SUM(Y22))/45>0.5,""yellow"",""red""))})"),"")
B3: 44958
B5: Week 1 | C5: ='Jan2023'!Q20+1 -> 44956 | D5: =C5+1 -> 44957 | E5: =D5+1 -> 44958 | F5: =E5+1 -> 44959 | G5: =F5+1 -> 44960 | H5: =G5+1 -> 44961 | I5: =H5+1 -> 44962 | K5: Week 2 | L5: =I5+1 -> 44963 | M5: =L5+1 -> 44964 | N5: =M5+1 -> 44965 | O5: =N5+1 -> 44966 | P5: =O5+1 -> 44967 | Q5: =P5+1 -> 44968 | R5: =Q5+1 -> 44969
B6: Day | C6: =CHOOSE(WEEKDAY(C5,2),"Mon","Tue","Wed","Thu","Fri","Sat","Sun") -> Mon | D6: =CHOOSE(WEEKDAY(D5,2),"Mon","Tue","Wed","Thu","Fri","Sat","Sun") -> Tue | E6: =CHOOSE(WEEKDAY(E5,2),"Mon","Tue","Wed","Thu","Fri","Sat","Sun") -> Wed | F6: =CHOOSE(WEEKDAY(F5,2),"Mon","Tue","Wed","Thu","Fri","Sat","Sun") -> Thu | G6: =CHOOSE(WEEKDAY(G5,2),"Mon","Tue","Wed","Thu","Fri","Sat","Sun") -> Fri | H6: =CHOOSE(WEEKDAY(H5,2),"Mon","Tue","Wed","Thu","Fri","Sat","Sun") -> Sat | I6: =CHOOSE(WEEKDAY(I5,2),"Mon","Tue","Wed","Thu","Fri","Sat","Sun") -> Sun | K6: Day | L6: =CHOOSE(WEEKDAY(L5,2),"Mon","Tue","Wed","Thu","Fri","Sat","Sun") -> Mon | M6: =CHOOSE(WEEKDAY(M5,2),"Mon","Tue","Wed","Thu","Fri","Sat","Sun") -> Tue | N6: =CHOOSE(WEEKDAY(N5,2),"Mon","Tue","Wed","Thu","Fri","Sat","Sun") -> Wed | O6: =CHOOSE(WEEKDAY(O5,2),"Mon","Tue","Wed","Thu","Fri","Sat","Sun") -> Thu | P6: =CHOOSE(WEEKDAY(P5,2),"Mon","Tue","Wed","Thu","Fri","Sat","Sun") -> Fri | Q6: =CHOOSE(WEEKDAY(Q5,2),"Mon","Tue","Wed","Thu","Fri","Sat","Sun") -> Sat | R6: =CHOOSE(WEEKDAY(R5,2),"Mon","Tue","Wed","Thu","Fri","Sat","Sun") -> Sun
B7: Exercise | C7: TRUE | D7: TRUE | E7: TRUE | F7: TRUE | G7: FALSE | H7: FALSE | I7: FALSE | K7: =B7 -> Exercise | L7: FALSE | M7: FALSE | N7: FALSE | O7: FALSE | P7: FALSE | Q7: FALSE | R7: FALSE | X7: =(SUM(C19:I19)+3*SUM(U19:V19) + SUM(L19:R19) + SUM(C37:I37) + SUM(L37:R37) + 3*SUM(U34:V34) + 5*SUM(Y22))/45 -> 0.69074074
B8: Stretch/Yoga (>20min) | C8: TRUE | D8: FALSE | E8: TRUE | F8: FALSE | G8: FALSE | H8: FALSE | I8: FALSE | K8: =B8 -> Stretch/Yoga (>20min) | L8: FALSE | M8: FALSE | N8: FALSE | O8: FALSE | P8: FALSE | Q8: FALSE | R8: FALSE | T8: Weekly Goals | U8: Week 1 | V8: Week 2 | X8: {=COUNTIF(C7:I18,TRUE)+COUNTIF(L7:R18,TRUE)+COUNTIF(C25:I36,TRUE)+COUNTIF(L25:R36,TRUE)+3*(COUNTIF(U9:V18,TRUE)+COUNTIF(U24:V33,TRUE))+5*(COUNTIF(Y17:Y21,TRUE))} -> 327
B9: Social Media (<limit) | C9: TRUE | D9: TRUE | E9: TRUE | F9: TRUE | G9: TRUE | H9: TRUE | I9: TRUE | K9: =B9 -> Social Media (<limit) | L9: TRUE | M9: TRUE | N9: TRUE | O9: TRUE | P9: TRUE | Q9: TRUE | R9: TRUE | T9: Laundry | U9: TRUE | V9: TRUE | X9: =X8 + 'Jan2023'!X1 -> 632
B10: Eat in | C10: TRUE | D10: TRUE | E10: TRUE | F10: TRUE | G10: TRUE | H10: TRUE | I10: TRUE | K10: =B10 -> Eat in | L10: TRUE | M10: TRUE | N10: TRUE | O10: TRUE | P10: FALSE | Q10: TRUE | R10: TRUE | T10: Cleaning | U10: TRUE | V10: TRUE
B11: Review Budget/Goals | C11: TRUE | D11: TRUE | E11: TRUE | F11: TRUE | G11: TRUE | H11: FALSE | I11: TRUE | K11: =B11 -> Review Budget/Goals | L11: TRUE | M11: TRUE | N11: TRUE | O11: TRUE | P11: TRUE | Q11: TRUE | R11: TRUE | T11: Grocery Shop | U11: TRUE | V11: TRUE
B12: (2x)Brush+(1x)Floss | C12: TRUE | D12: TRUE | E12: TRUE | F12: TRUE | G12: FALSE | H12: FALSE | I12: FALSE | K12: =B12 -> (2x)Brush+(1x)Floss | L12: FALSE | M12: TRUE | N12: FALSE | O12: FALSE | P12: FALSE | Q12: FALSE | R12: TRUE | T12: Meal Prep | U12: FALSE | V12: TRUE
B13: Water (2.25L+) | C13: TRUE | D13: FALSE | E13: TRUE | F13: TRUE | G13: FALSE | H13: FALSE | I13: FALSE | K13: =B13 -> Water (2.25L+) | L13: FALSE | M13: FALSE | N13: FALSE | O13: FALSE | P13: FALSE | Q13: TRUE | R13: TRUE | T13: Website work (~2h) | U13: FALSE | V13: TRUE
B14: 7 hours sleep | C14: FALSE | D14: FALSE | E14: TRUE | F14: TRUE | G14: FALSE | H14: FALSE | I14: FALSE | K14: =B14 -> 7 hours sleep | L14: TRUE | M14: TRUE | N14: TRUE | O14: TRUE | P14: TRUE | Q14: TRUE | R14: FALSE | T14: Recycling | U14: TRUE | V14: TRUE
B15: Clean (~20 min) | C15: TRUE | D15: FALSE | E15: TRUE | F15: FALSE | G15: FALSE | H15: FALSE | I15: TRUE | K15: =B15 -> Clean (~20 min) | L15: TRUE | M15: TRUE | N15: TRUE | O15: FALSE | P15: TRUE | Q15: TRUE | R15: TRUE | T15: Trash | U15: FALSE | V15: TRUE
